Workbook

Sheet 発注書
H1: 着日 | I1: 2025年12月9日 | L1: 最小ロット…おかず36食＋ライス36食 | O1: 株式会社ジョイント
C2: コード | D2: 名称
B3: 発注先 | C3: bb02787 | D3: イルミナジョブ＆カレッジ千葉中央校 | L3: おかずのみ…54食（ヤマト運輸） | O3: ライスのみ…70食（ヤマト運輸）
C4: 7日～13日着専用 | L4: おかずのみ…63食（佐川急便） | O4: ライスのみ…80食（佐川急便）
B5: 03 | C5: =VLOOKUP(B5,商品分類!$A$2:$B$81,2) -> 健康管理食選択型 | D5: 数量 | F5: =VLOOKUP(E5,商品分類!$A$2:$B$81,2) -> #N/A | G5: 数量 | I5: =VLOOKUP(H5,商品分類!$A$2:$B$81,2) -> #N/A | J5: 数量 | L5: =VLOOKUP(K5,商品分類!$A$2:$B$81,2) -> #N/A | M5: 数量 | O5: =VLOOKUP(N5,商品分類!$A$2:$B$81,2) -> #N/A | P5: 数量 | R5: 180gライス
A6: 1 | B6: =IFERROR(VLOOKUP(B$5&TEXT($A6,"000"),商品!$B$1:$E$1846,1,FALSE),"") -> 03001 | C6: =IFERROR(VLOOKUP(B6,商品!$B$1:$E$1846,2,FALSE),"") -> たらの牛だしあん | E6: =IFERROR(VLOOKUP(E$5&TEXT($A6,"000"),商品!$B$1:$E$1846,1,FALSE),"") | F6: =IFERROR(VLOOKUP(E6,商品!$B$1:$E$1846,2,FALSE),"") | H6: =IFERROR(VLOOKUP(H$5&TEXT($A6,"000"),商品!$B$1:$E$1846,1,FALSE),"") | I6: =IFERROR(VLOOKUP(H6,商品!$B$1:$E$1846,2,FALSE),"") | K6: =IFERROR(VLOOKUP(K$5&TEXT($A6,"000"),商品!$B$1:$E$1846,1,FALSE),"") | L6: =IFERROR(VLOOKUP(K6,商品!$B$1:$E$1846,2,FALSE),"") | N6: =IFERROR(VLOOKUP(N$5&TEXT($A6,"000"),商品!$B$1:$E$1846,1,FALSE),"") | O6: =IFERROR(VLOOKUP(N6,商品!$B$1:$E$1846,2,FALSE),"")
A7: 2 | B7: =IFERROR(VLOOKUP(B$5&TEXT($A7,"000"),商品!$B$1:$E$1846,1,FALSE),"") -> 03002 | C7: =IFERROR(VLOOKUP(B7,商品!$B$1:$E$1846,2,FALSE),"") -> 豚バラ肉の豆乳ソースがけ | D7: 4 | E7: =IFERROR(VLOOKUP(E$5&TEXT($A7,"000"),商品!$B$1:$E$1846,1,FALSE),"") | F7: =IFERROR(VLOOKUP(E7,商品!$B$1:$E$1846,2,FALSE),"") | H7: =IFERROR(VLOOKUP(H$5&TEXT($A7,"000"),商品!$B$1:$E$1846,1,FALSE),"") | I7: =IFERROR(VLOOKUP(H7,商品!$B$1:$E$1846,2,FALSE),"") | K7: =IFERROR(VLOOKUP(K$5&TEXT($A7,"000"),商品!$B$1:$E$1846,1,FALSE),"") | L7: =IFERROR(VLOOKUP(K7,商品!$B$1:$E$1846,2,FALSE),"") | N7: =IFERROR(VLOOKUP(N$5&TEXT($A7,"000"),商品!$B$1:$E$1846,1,FALSE),"") | O7: =IFERROR(VLOOKUP(N7,商品!$B$1:$E$1846,2,FALSE),"") | R7: 72
A8: 3 | B8: =IFERROR(VLOOKUP(B$5&TEXT($A8,"000"),商品!$B$1:$E$1846,1,FALSE),"") -> 03003 | C8: =IFERROR(VLOOKUP(B8,商品!$B$1:$E$1846,2,FALSE),"") -> エビカツ | D8: 4 | E8: =IFERROR(VLOOKUP(E$5&TEXT($A8,"000"),商品!$B$1:$E$1846,1,FALSE),"") | F8: =IFERROR(VLOOKUP(E8,商品!$B$1:$E$1846,2,FALSE),"") | H8: =IFERROR(VLOOKUP(H$5&TEXT($A8,"000"),商品!$B$1:$E$1846,1,FALSE),"") | I8: =IFERROR(VLOOKUP(H8,商品!$B$1:$E$1846,2,FALSE),"") | K8: =IFERROR(VLOOKUP(K$5&TEXT($A8,"000"),商品!$B$1:$E$1846,1,FALSE),"") | L8: =IFERROR(VLOOKUP(K8,商品!$B$1:$E$1846,2,FALSE),"") | N8: =IFERROR(VLOOKUP(N$5&TEXT($A8,"000"),商品!$B$1:$E$1846,1,FALSE),"") | O8: =IFERROR(VLOOKUP(N8,商品!$B$1:$E$1846,2,FALSE),"")
A9: 4 | B9: =IFERROR(VLOOKUP(B$5&TEXT($A9,"000"),商品!$B$1:$E$1846,1,FALSE),"") -> 03004 | C9: =IFERROR(VLOOKUP(B9,商品!$B$1:$E$1846,2,FALSE),"") -> 鶏のから揚げ | D9: 4 | E9: =IFERROR(VLOOKUP(E$5&TEXT($A9,"000"),商品!$B$1:$E$1846,1,FALSE),"") | F9: =IFERROR(VLOOKUP(E9,商品!$B$1:$E$1846,2,FALSE),"") | H9: =IFERROR(VLOOKUP(H$5&TEXT($A9,"000"),商品!$B$1:$E$1846,1,FALSE),"") | I9: =IFERROR(VLOOKUP(H9,商品!$B$1:$E$1846,2,FALSE),"") | K9: =IFERROR(VLOOKUP(K$5&TEXT($A9,"000"),商品!$B$1:$E$1846,1,FALSE),"") | L9: =IFERROR(VLOOKUP(K9,商品!$B$1:$E$1846,2,FALSE),"") | N9: =IFERROR(VLOOKUP(N$5&TEXT($A9,"000"),商品!$B$1:$E$1846,1,FALSE),"") | O9: =IFERROR(VLOOKUP(N9,商品!$B$1:$E$1846,2,FALSE),"")
A10: 5 | B10: =IFERROR(VLOOKUP(B$5&TEXT($A10,"000"),商品!$B$1:$E$1846,1,FALSE),"") -> 03005 | C10: =IFERROR(VLOOKUP(B10,商品!$B$1:$E$1846,2,FALSE),"") -> すき焼き風煮 | D10: 8 | E10: =IFERROR(VLOOKUP(E$5&TEXT($A10,"000"),商品!$B$1:$E$1846,1,FALSE),"") | F10: =IFERROR(VLOOKUP(E10,商品!$B$1:$E$1846,2,FALSE),"") | H10: =IFERROR(VLOOKUP(H$5&TEXT($A10,"000"),商品!$B$1:$E$1846,1,FALSE),"") | I10: =IFERROR(VLOOKUP(H10,商品!$B$1:$E$1846,2,FALSE),"") | K10: =IFERROR(VLOOKUP(K$5&TEXT($A10,"000"),商品!$B$1:$E$1846,1,FALSE),"") | L10: =IFERROR(VLOOKUP(K10,商品!$B$1:$E$1846,2,FALSE),"") | N10: =IFERROR(VLOOKUP(N$5&TEXT($A10,"000"),商品!$B$1:$E$1846,1,FALSE),"") | O10: =IFERROR(VLOOKUP(N10,商品!$B$1:$E$1846,2,FALSE),"") | R10: 150gライス
A11: 6 | B11: =IFERROR(VLOOKUP(B$5&TEXT($A11,"000"),商品!$B$1:$E$1846,1,FALSE),"") -> 03006 | C11: =IFERROR(VLOOKUP(B11,商品!$B$1:$E$1846,2,FALSE),"") -> 鶏肉のタンドリー風焼き | D11: 4 | E11: =IFERROR(VLOOKUP(E$5&TEXT($A11,"000"),商品!$B$1:$E$1846,1,FALSE),"") | F11: =IFERROR(VLOOKUP(E11,商品!$B$1:$E$1846,2,FALSE),"") | H11: =IFERROR(VLOOKUP(H$5&TEXT($A11,"000"),商品!$B$1:$E$1846,1,FALSE),"") | I11: =IFERROR(VLOOKUP(H11,商品!$B$1:$E$1846,2,FALSE),"") | K11: =IFERROR(VLOOKUP(K$5&TEXT($A11,"000"),商品!$B$1:$E$1846,1,FALSE),"") | L11: =IFERROR(VLOOKUP(K11,商品!$B$1:$E$1846,2,FALSE),"") | N11: =IFERROR(VLOOKUP(N$5&TEXT($A11,"000"),商品!$B$1:$E$1846,1,FALSE),"") | O11: =IFERROR(VLOOKUP(N11,商品!$B$1:$E$1846,2,FALSE),"")
A12: 7 | B12: =IFERROR(VLOOKUP(B$5&TEXT($A12,"000"),商品!$B$1:$E$1846,1,FALSE),"") -> 03007 | C12: =IFERROR(VLOOKUP(B12,商品!$B$1:$E$1846,2,FALSE),"") -> トマトソースのチーズハンバーグ | D12: 4 | E12: =IFERROR(VLOOKUP(E$5&TEXT($A12,"000"),商品!$B$1:$E$1846,1,FALSE),"") | F12: =IFERROR(VLOOKUP(E12,商品!$B$1:$E$1846,2,FALSE),"") | H12: =IFERROR(VLOOKUP(H$5&TEXT($A12,"000"),商品!$B$1:$E$1846,1,FALSE),"") | I12: =IFERROR(VLOOKUP(H12,商品!$B$1:$E$1846,2,FALSE),"") | K12: =IFERROR(VLOOKUP(K$5&TEXT($A12,"000"),商品!$B$1:$E$1846,1,FALSE),"") | L12: =IFERROR(VLOOKUP(K12,商品!$B$1:$E$1846,2,FALSE),"") | N12: =IFERROR(VLOOKUP(N$5&TEXT($A12,"000"),商品!$B$1:$E$1846,1,FALSE),"") | O12: =IFERROR(VLOOKUP(N12,商品!$B$1:$E$1846,2,FALSE),"")
A13: 8 | B13: =IFERROR(VLOOKUP(B$5&TEXT($A13,"000"),商品!$B$1:$E$1846,1,FALSE),"") -> 03008 | C13: =IFERROR(VLOOKUP(B13,商品!$B$1:$E$1846,2,FALSE),"") -> カレイのねぎ塩焼き | E13: =IFERROR(VLOOKUP(E$5&TEXT($A13,"000"),商品!$B$1:$E$1846,1,FALSE),"") | F13: =IFERROR(VLOOKUP(E13,商品!$B$1:$E$1846,2,FALSE),"") | H13: =IFERROR(VLOOKUP(H$5&TEXT($A13,"000"),商品!$B$1:$E$1846,1,FALSE),"") | I13: =IFERROR(VLOOKUP(H13,商品!$B$1:$E$1846,2,FALSE),"") | K13: =IFERROR(VLOOKUP(K$5&TEXT($A13,"000"),商品!$B$1:$E$1846,1,FALSE),"") | L13: =IFERROR(VLOOKUP(K13,商品!$B$1:$E$1846,2,FALSE),"") | N13: =IFERROR(VLOOKUP(N$5&TEXT($A13,"000"),商品!$B$1:$E$1846,1,FALSE),"") | O13: =IFERROR(VLOOKUP(N13,商品!$B$1:$E$1846,2,FALSE),"")
A14: 9 | B14: =IFERROR(VLOOKUP(B$5&TEXT($A14,"000"),商品!$B$1:$E$1846,1,FALSE),"") -> 03009 | C14: =IFERROR(VLOOKUP(B14,商品!$B$1:$E$1846,2,FALSE),"") -> タラのみぞれかけ | E14: =IFERROR(VLOOKUP(E$5&TEXT($A14,"000"),商品!$B$1:$E$1846,1,FALSE),"") | F14: =IFERROR(VLOOKUP(E14,商品!$B$1:$E$1846,2,FALSE),"") | H14: =IFERROR(VLOOKUP(H$5&TEXT($A14,"000"),商品!$B$1:$E$1846,1,FALSE),"") | I14: =IFERROR(VLOOKUP(H14,商品!$B$1:$E$1846,2,FALSE),"") | K14: =IFERROR(VLOOKUP(K$5&TEXT($A14,"000"),商品!$B$1:$E$1846,1,FALSE),"") | L14: =IFERROR(VLOOKUP(K14,商品!$B$1:$E$1846,2,FALSE),"") | N14: =IFERROR(VLOOKUP(N$5&TEXT($A14,"000"),商品!$B$1:$E$1846,1,FALSE),"") | O14: =IFERROR(VLOOKUP(N14,商品!$B$1:$E$1846,2,FALSE),"")
A15: 10 | B15: =IFERROR(VLOOKUP(B$5&TEXT($A15,"000"),商品!$B$1:$E$1846,1,FALSE),"") -> 03010 | C15: =IFERROR(VLOOKUP(B15,商品!$B$1:$E$1846,2,FALSE),"") -> 和風カツの卵とじ | E15: =IFERROR(VLOOKUP(E$5&TEXT($A15,"000"),商品!$B$1:$E$1846,1,FALSE),"") | F15: =IFERROR(VLOOKUP(E15,商品!$B$1:$E$1846,2,FALSE),"") | H15: =IFERROR(VLOOKUP(H$5&TEXT($A15,"000"),商品!$B$1:$E$1846,1,FALSE),"") | I15: =IFERROR(VLOOKUP(H15,商品!$B$1:$E$1846,2,FALSE),"") | K15: =IFERROR(VLOOKUP(K$5&TEXT($A15,"000"),商品!$B$1:$E$1846,1,FALSE),"") | L15: =IFERROR(VLOOKUP(K15,商品!$B$1:$E$1846,2,FALSE),"") | N15: =IFERROR(VLOOKUP(N$5&TEXT($A15,"000"),商品!$B$1:$E$1846,1,FALSE),"") | O15: =IFERROR(VLOOKUP(N15,商品!$B$1:$E$1846,2,FALSE),"")
A16: 11 | B16: =IFERROR(VLOOKUP(B$5&TEXT($A16,"000"),商品!$B$1:$E$1846,1,FALSE),"") -> 03011 | C16: =IFERROR(VLOOKUP(B16,商品!$B$1:$E$1846,2,FALSE),"") -> みそカツ | E16: =IFERROR(VLOOKUP(E$5&TEXT($A16,"000"),商品!$B$1:$E$1846,1,FALSE),"") | F16: =IFERROR(VLOOKUP(E16,商品!$B$1:$E$1846,2,FALSE),"") | H16: =IFERROR(VLOOKUP(H$5&TEXT($A16,"000"),商品!$B$1:$E$1846,1,FALSE),"") | I16: =IFERROR(VLOOKUP(H16,商品!$B$1:$E$1846,2,FALSE),"") | K16: =IFERROR(VLOOKUP(K$5&TEXT($A16,"000"),商品!$B$1:$E$1846,1,FALSE),"") | L16: =IFERROR(VLOOKUP(K16,商品!$B$1:$E$1846,2,FALSE),"") | N16: =IFERROR(VLOOKUP(N$5&TEXT($A16,"000"),商品!$B$1:$E$1846,1,FALSE),"") | O16: =IFERROR(VLOOKUP(N16,商品!$B$1:$E$1846,2,FALSE),"")
A17: 12 | B17: =IFERROR(VLOOKUP(B$5&TEXT($A17,"000"),商品!$B$1:$E$1846,1,FALSE),"") -> 03012 | C17: =IFERROR(VLOOKUP(B17,商品!$B$1:$E$1846,2,FALSE),"") -> 豚肉のタッカルビ風 | E17: =IFERROR(VLOOKUP(E$5&TEXT($A17,"000"),商品!$B$1:$E$1846,1,FALSE),"") | F17: =IFERROR(VLOOKUP(E17,商品!$B$1:$E$1846,2,FALSE),"") | H17: =IFERROR(VLOOKUP(H$5&TEXT($A17,"000"),商品!$B$1:$E$1846,1,FALSE),"") | I17: =IFERROR(VLOOKUP(H17,商品!$B$1:$E$1846,2,FALSE),"") | K17: =IFERROR(VLOOKUP(K$5&TEXT($A17,"000"),商品!$B$1:$E$1846,1,FALSE),"") | L17: =IFERROR(VLOOKUP(K17,商品!$B$1:$E$1846,2,FALSE),"") | N17: =IFERROR(VLOOKUP(N$5&TEXT($A17,"000"),商品!$B$1:$E$1846,1,FALSE),"") | O17: =IFERROR(VLOOKUP(N17,商品!$B$1:$E$1846,2,FALSE),"")
A18: 13 | B18: =IFERROR(VLOOKUP(B$5&TEXT($A18,"000"),商品!$B$1:$E$1846,1,FALSE),"") -> 03013 | C18: =IFERROR(VLOOKUP(B18,商品!$B$1:$E$1846,2,FALSE),"") -> 焼きサバの梅ソースがけ | E18: =IFERROR(VLOOKUP(E$5&TEXT($A18,"000"),商品!$B$1:$E$1846,1,FALSE),"") | F18: =IFERROR(VLOOKUP(E18,商品!$B$1:$E$1846,2,FALSE),"") | H18: =IFERROR(VLOOKUP(H$5&TEXT($A18,"000"),商品!$B$1:$E$1846,1,FALSE),"") | I18: =IFERROR(VLOOKUP(H18,商品!$B$1:$E$1846,2,FALSE),"") | K18: =IFERROR(VLOOKUP(K$5&TEXT($A18,"000"),商品!$B$1:$E$1846,1,FALSE),"") | L18: =IFERROR(VLOOKUP(K18,商品!$B$1:$E$1846,2,FALSE),"") | N18: =IFERROR(VLOOKUP(N$5&TEXT($A18,"000"),商品!$B$1:$E$1846,1,FALSE),"") | O18: =IFERROR(VLOOKUP(N18,商品!$B$1:$E$1846,2,FALSE),"")
A19: 14 | B19: =IFERROR(VLOOKUP(B$5&TEXT($A19,"000"),商品!$B$1:$E$1846,1,FALSE),"") -> 03014 | C19: =IFERROR(VLOOKUP(B19,商品!$B$1:$E$1846,2,FALSE),"") -> 赤魚の紅生姜あんかけ | E19: =IFERROR(VLOOKUP(E$5&TEXT($A19,"000"),商品!$B$1:$E$1846,1,FALSE),"") | F19: =IFERROR(VLOOKUP(E19,商品!$B$1:$E$1846,2,FALSE),"") | H19: =IFERROR(VLOOKUP(H$5&TEXT($A19,"000"),商品!$B$1:$E$1846,1,FALSE),"") | I19: =IFERROR(VLOOKUP(H19,商品!$B$1:$E$1846,2,FALSE),"") | K19: =IFERROR(VLOOKUP(K$5&TEXT($A19,"000"),商品!$B$1:$E$1846,1,FALSE),"") | L19: =IFERROR(VLOOKUP(K19,商品!$B$1:$E$1846,2,FALSE),"") | N19: =IFERROR(VLOOKUP(N$5&TEXT($A19,"000"),商品!$B$1:$E$1846,1,FALSE),"") | O19: =IFERROR(VLOOKUP(N19,商品!$B$1:$E$1846,2,FALSE),"")
A20: 15 | B20: =IFERROR(VLOOKUP(B$5&TEXT($A20,"000"),商品!$B$1:$E$1846,1,FALSE),"") -> 03015 | C20: =IFERROR(VLOOKUP(B20,商品!$B$1:$E$1846,2,FALSE),"") -> 豆腐ハンバーグ麻婆ソース | E20: =IFERROR(VLOOKUP(E$5&TEXT($A20,"000"),商品!$B$1:$E$1846,1,FALSE),"") | F20: =IFERROR(VLOOKUP(E20,商品!$B$1:$E$1846,2,FALSE),"") | H20: =IFERROR(VLOOKUP(H$5&TEXT($A20,"000"),商品!$B$1:$E$1846,1,FALSE),"") | I20: =IFERROR(VLOOKUP(H20,商品!$B$1:$E$1846,2,FALSE),"") | K20: =IFERROR(VLOOKUP(K$5&TEXT($A20,"000"),商品!$B$1:$E$1846,1,FALSE),"") | L20: =IFERROR(VLOOKUP(K20,商品!$B$1:$E$1846,2,FALSE),"") | N20: =IFERROR(VLOOKUP(N$5&TEXT($A20,"000"),商品!$B$1:$E$1846,1,FALSE),"") | O20: =IFERROR(VLOOKUP(N20,商品!$B$1:$E$1846,2,FALSE),"")
A21: 16 | B21: =IFERROR(VLOOKUP(B$5&TEXT($A21,"000"),商品!$B$1:$E$1846,1,FALSE),"") -> 03016 | C21: =IFERROR(VLOOKUP(B21,商品!$B$1:$E$1846,2,FALSE),"") -> カレイのバターポン酢きのこあん | D21: 8 | E21: =IFERROR(VLOOKUP(E$5&TEXT($A21,"000"),商品!$B$1:$E$1846,1,FALSE),"") | F21: =IFERROR(VLOOKUP(E21,商品!$B$1:$E$1846,2,FALSE),"") | H21: =IFERROR(VLOOKUP(H$5&TEXT($A21,"000"),商品!$B$1:$E$1846,1,FALSE),"") | I21: =IFERROR(VLOOKUP(H21,商品!$B$1:$E$1846,2,FALSE),"") | K21: =IFERROR(VLOOKUP(K$5&TEXT($A21,"000"),商品!$B$1:$E$1846,1,FALSE),"") | L21: =IFERROR(VLOOKUP(K21,商品!$B$1:$E$1846,2,FALSE),"") | N21: =IFERROR(VLOOKUP(N$5&TEXT($A21,"000"),商品!$B$1:$E$1846,1,FALSE),"") | O21: =IFERROR(VLOOKUP(N21,商品!$B$1:$E$1846,2,FALSE),"")
A22: 17 | B22: =IFERROR(VLOOKUP(B$5&TEXT($A22,"000"),商品!$B$1:$E$1846,1,FALSE),"") -> 03017 | C22: =IFERROR(VLOOKUP(B22,商品!$B$1:$E$1846,2,FALSE),"") -> 広東風かに玉 | E22: =IFERROR(VLOOKUP(E$5&TEXT($A22,"000"),商品!$B$1:$E$1846,1,FALSE),"") | F22: =IFERROR(VLOOKUP(E22,商品!$B$1:$E$1846,2,FALSE),"") | H22: =IFERROR(VLOOKUP(H$5&TEXT($A22,"000"),商品!$B$1:$E$1846,1,FALSE),"") | I22: =IFERROR(VLOOKUP(H22,商品!$B$1:$E$1846,2,FALSE),"") | K22: =IFERROR(VLOOKUP(K$5&TEXT($A22,"000"),商品!$B$1:$E$1846,1,FALSE),"") | L22: =IFERROR(VLOOKUP(K22,商品!$B$1:$E$1846,2,FALSE),"") | N22: =IFERROR(VLOOKUP(N$5&TEXT($A22,"000"),商品!$B$1:$E$1846,1,FALSE),"") | O22: =IFERROR(VLOOKUP(N22,商品!$B$1:$E$1846,2,FALSE),"")
A23: 18 | B23: =IFERROR(VLOOKUP(B$5&TEXT($A23,"000"),商品!$B$1:$E$1846,1,FALSE),"") -> 03018 | C23: =IFERROR(VLOOKUP(B23,商品!$B$1:$E$1846,2,FALSE),"") -> メバルの幽庵焼き | E23: =IFERROR(VLOOKUP(E$5&TEXT($A23,"000"),商品!$B$1:$E$1846,1,FALSE),"") | F23: =IFERROR(VLOOKUP(E23,商品!$B$1:$E$1846,2,FALSE),"") | H23: =IFERROR(VLOOKUP(H$5&TEXT($A23,"000"),商品!$B$1:$E$1846,1,FALSE),"") | I23: =IFERROR(VLOOKUP(H23,商品!$B$1:$E$1846,2,FALSE),"") | K23: =IFERROR(VLOOKUP(K$5&TEXT($A23,"000"),商品!$B$1:$E$1846,1,FALSE),"") | L23: =IFERROR(VLOOKUP(K23,商品!$B$1:$E$1846,2,FALSE),"") | N23: =IFERROR(VLOOKUP(N$5&TEXT($A23,"000"),商品!$B$1:$E$1846,1,FALSE),"") | O23: =IFERROR(VLOOKUP(N23,商品!$B$1:$E$1846,2,FALSE),"")
A24: 19 | B24: =IFERROR(VLOOKUP(B$5&TEXT($A24,"000"),商品!$B$1:$E$1846,1,FALSE),"") -> 03019 | C24: =IFERROR(VLOOKUP(B24,商品!$B$1:$E$1846,2,FALSE),"") -> ハンバーグ玉葱ソース | E24: =IFERROR(VLOOKUP(E$5&TEXT($A24,"000"),商品!$B$1:$E$1846,1,FALSE),"") | F24: =IFERROR(VLOOKUP(E24,商品!$B$1:$E$1846,2,FALSE),"") | H24: =IFERROR(VLOOKUP(H$5&TEXT($A24,"000"),商品!$B$1:$E$1846,1,FALSE),"") | I24: =IFERROR(VLOOKUP(H24,商品!$B$1:$E$1846,2,FALSE),"") | K24: =IFERROR(VLOOKUP(K$5&TEXT($A24,"000"),商品!$B$1:$E$1846,1,FALSE),"") | L24: =IFERROR(VLOOKUP(K24,商品!$B$1:$E$1846,2,FALSE),"") | N24: =IFERROR(VLOOKUP(N$5&TEXT($A24,"000"),商品!$B$1:$E$1846,1,FALSE),"") | O24: =IFERROR(VLOOKUP(N24,商品!$B$1:$E$1846,2,FALSE),"")
A25: 20 | B25: =IFERROR(VLOOKUP(B$5&TEXT($A25,"000"),商品!$B$1:$E$1846,1,FALSE),"") -> 03020 | C25: =IFERROR(VLOOKUP(B25,商品!$B$1:$E$1846,2,FALSE),"") -> 牛肉のチャプチェ | E25: =IFERROR(VLOOKUP(E$5&TEXT($A25,"000"),商品!$B$1:$E$1846,1,FALSE),"") | F25: =IFERROR(VLOOKUP(E25,商品!$B$1:$E$1846,2,FALSE),"") | H25: =IFERROR(VLOOKUP(H$5&TEXT($A25,"000"),商品!$B$1:$E$1846,1,FALSE),"") | I25: =IFERROR(VLOOKUP(H25,商品!$B$1:$E$1846,2,FALSE),"") | K25: =IFERROR(VLOOKUP(K$5&TEXT($A25,"000"),商品!$B$1:$E$1846,1,FALSE),"") | L25: =IFERROR(VLOOKUP(K25,商品!$B$1:$E$1846,2,FALSE),"") | N25: =IFERROR(VLOOKUP(N$5&TEXT($A25,"000"),商品!$B$1:$E$1846,1,FALSE),"") | O25: =IFERROR(VLOOKUP(N25,商品!$B$1:$E$1846,2,FALSE),"")
A26: 21 | B26: =IFERROR(VLOOKUP(B$5&TEXT($A26,"000"),商品!$B$1:$E$1846,1,FALSE),"") -> 03021 | C26: =IFERROR(VLOOKUP(B26,商品!$B$1:$E$1846,2,FALSE),"") -> 豚しゃぶ柚子おろしだれ | E26: =IFERROR(VLOOKUP(E$5&TEXT($A26,"000"),商品!$B$1:$E$1846,1,FALSE),"") | F26: =IFERROR(VLOOKUP(E26,商品!$B$1:$E$1846,2,FALSE),"") | H26: =IFERROR(VLOOKUP(H$5&TEXT($A26,"000"),商品!$B$1:$E$1846,1,FALSE),"") | I26: =IFERROR(VLOOKUP(H26,商品!$B$1:$E$1846,2,FALSE),"") | K26: =IFERROR(VLOOKUP(K$5&TEXT($A26,"000"),商品!$B$1:$E$1846,1,FALSE),"") | L26: =IFERROR(VLOOKUP(K26,商品!$B$1:$E$1846,2,FALSE),"") | N26: =IFERROR(VLOOKUP(N$5&TEXT($A26,"000"),商品!$B$1:$E$1846,1,FALSE),"") | O26: =IFERROR(VLOOKUP(N26,商品!$B$1:$E$1846,2,FALSE),"")
A27: 22 | B27: =IFERROR(VLOOKUP(B$5&TEXT($A27,"000"),商品!$B$1:$E$1846,1,FALSE),"") -> 03022 | C27: =IFERROR(VLOOKUP(B27,商品!$B$1:$E$1846,2,FALSE),"") -> サワラの洋風焼き | E27: =IFERROR(VLOOKUP(E$5&TEXT($A27,"000"),商品!$B$1:$E$1846,1,FALSE),"") | F27: =IFERROR(VLOOKUP(E27,商品!$B$1:$E$1846,2,FALSE),"") | H27: =IFERROR(VLOOKUP(H$5&TEXT($A27,"000"),商品!$B$1:$E$1846,1,FALSE),"") | I27: =IFERROR(VLOOKUP(H27,商品!$B$1:$E$1846,2,FALSE),"") | K27: =IFERROR(VLOOKUP(K$5&TEXT($A27,"000"),商品!$B$1:$E$1846,1,FALSE),"") | L27: =IFERROR(VLOOKUP(K27,商品!$B$1:$E$1846,2,FALSE),"") | N27: =IFERROR(VLOOKUP(N$5&TEXT($A27,"000"),商品!$B$1:$E$1846,1,FALSE),"") | O27: =IFERROR(VLOOKUP(N27,商品!$B$1:$E$1846,2,FALSE),"")
A28: 23 | B28: =IFERROR(VLOOKUP(B$5&TEXT($A28,"000"),商品!$B$1:$E$1846,1,FALSE),"") -> 03023 | C28: =IFERROR(VLOOKUP(B28,商品!$B$1:$E$1846,2,FALSE),"") -> 豚肉の生姜焼き | E28: =IFERROR(VLOOKUP(E$5&TEXT($A28,"000"),商品!$B$1:$E$1846,1,FALSE),"") | F28: =IFERROR(VLOOKUP(E28,商品!$B$1:$E$1846,2,FALSE),"") | H28: =IFERROR(VLOOKUP(H$5&TEXT($A28,"000"),商品!$B$1:$E$1846,1,FALSE),"") | I28: =IFERROR(VLOOKUP(H28,商品!$B$1:$E$1846,2,FALSE),"") | K28: =IFERROR(VLOOKUP(K$5&TEXT($A28,"000"),商品!$B$1:$E$1846,1,FALSE),"") | L28: =IFERROR(VLOOKUP(K28,商品!$B$1:$E$1846,2,FALSE),"") | N28: =IFERROR(VLOOKUP(N$5&TEXT($A28,"000"),商品!$B$1:$E$1846,1,FALSE),"") | O28: =IFERROR(VLOOKUP(N28,商品!$B$1:$E$1846,2,FALSE),"")
A29: 24 | B29: =IFERROR(VLOOKUP(B$5&TEXT($A29,"000"),商品!$B$1:$E$1846,1,FALSE),"") -> 03024 | C29: =IFERROR(VLOOKUP(B29,商品!$B$1:$E$1846,2,FALSE),"") -> 赤魚の煮付け | E29: =IFERROR(VLOOKUP(E$5&TEXT($A29,"000"),商品!$B$1:$E$1846,1,FALSE),"") | F29: =IFERROR(VLOOKUP(E29,商品!$B$1:$E$1846,2,FALSE),"") | H29: =IFERROR(VLOOKUP(H$5&TEXT($A29,"000"),商品!$B$1:$E$1846,1,FALSE),"") | I29: =IFERROR(VLOOKUP(H29,商品!$B$1:$E$1846,2,FALSE),"") | K29: =IFERROR(VLOOKUP(K$5&TEXT($A29,"000"),商品!$B$1:$E$1846,1,FALSE),"") | L29: =IFERROR(VLOOKUP(K29,商品!$B$1:$E$1846,2,FALSE),"") | N29: =IFERROR(VLOOKUP(N$5&TEXT($A29,"000"),商品!$B$1:$E$1846,1,FALSE),"") | O29: =IFERROR(VLOOKUP(N29,商品!$B$1:$E$1846,2,FALSE),"")
A30: 25 | B30: =IFERROR(VLOOKUP(B$5&TEXT($A30,"000"),商品!$B$1:$E$1846,1,FALSE),"") -> 03025 | C30: =IFERROR(VLOOKUP(B30,商品!$B$1:$E$1846,2,FALSE),"") -> チキンカツの梅マヨソース | E30: =IFERROR(VLOOKUP(E$5&TEXT($A30,"000"),商品!$B$1:$E$1846,1,FALSE),"") | F30: =IFERROR(VLOOKUP(E30,商品!$B$1:$E$1846,2,FALSE),"") | H30: =IFERROR(VLOOKUP(H$5&TEXT($A30,"000"),商品!$B$1:$E$1846,1,FALSE),"") | I30: =IFERROR(VLOOKUP(H30,商品!$B$1:$E$1846,2,FALSE),"") | K30: =IFERROR(VLOOKUP(K$5&TEXT($A30,"000"),商品!$B$1:$E$1846,1,FALSE),"") | L30: =IFERROR(VLOOKUP(K30,商品!$B$1:$E$1846,2,FALSE),"") | N30: =IFERROR(VLOOKUP(N$5&TEXT($A30,"000"),商品!$B$1:$E$1846,1,FALSE),"") | O30: =IFERROR(VLOOKUP(N30,商品!$B$1:$E$1846,2,FALSE),"")
A31: 26 | B31: =IFERROR(VLOOKUP(B$5&TEXT($A31,"000"),商品!$B$1:$E$1846,1,FALSE),"") -> 03026 | C31: =IFERROR(VLOOKUP(B31,商品!$B$1:$E$1846,2,FALSE),"") -> 肉じゃが | E31: =IFERROR(VLOOKUP(E$5&TEXT($A31,"000"),商品!$B$1:$E$1846,1,FALSE),"") | F31: =IFERROR(VLOOKUP(E31,商品!$B$1:$E$1846,2,FALSE),"") | H31: =IFERROR(VLOOKUP(H$5&TEXT($A31,"000"),商品!$B$1:$E$1846,1,FALSE),"") | I31: =IFERROR(VLOOKUP(H31,商品!$B$1:$E$1846,2,FALSE),"") | K31: =IFERROR(VLOOKUP(K$5&TEXT($A31,"000"),商品!$B$1:$E$1846,1,FALSE),"") | L31: =IFERROR(VLOOKUP(K31,商品!$B$1:$E$1846,2,FALSE),"") | N31: =IFERROR(VLOOKUP(N$5&TEXT($A31,"000"),商品!$B$1:$E$1846,1,FALSE),"") | O31: =IFERROR(VLOOKUP(N31,商品!$B$1:$E$1846,2,FALSE),"")
A32: 27 | B32: =IFERROR(VLOOKUP(B$5&TEXT($A32,"000"),商品!$B$1:$E$1846,1,FALSE),"") -> 03027 | C32: =IFERROR(VLOOKUP(B32,商品!$B$1:$E$1846,2,FALSE),"") -> 鶏肉のスイートチリソース | E32: =IFERROR(VLOOKUP(E$5&TEXT($A32,"000"),商品!$B$1:$E$1846,1,FALSE),"") | F32: =IFERROR(VLOOKUP(E32,商品!$B$1:$E$1846,2,FALSE),"") | H32: =IFERROR(VLOOKUP(H$5&TEXT($A32,"000"),商品!$B$1:$E$1846,1,FALSE),"") | I32: =IFERROR(VLOOKUP(H32,商品!$B$1:$E$1846,2,FALSE),"") | K32: =IFERROR(VLOOKUP(K$5&TEXT($A32,"000"),商品!$B$1:$E$1846,1,FALSE),"") | L32: =IFERROR(VLOOKUP(K32,商品!$B$1:$E$1846,2,FALSE),"") | N32: =IFERROR(VLOOKUP(N$5&TEXT($A32,"000"),商品!$B$1:$E$1846,1,FALSE),"") | O32: =IFERROR(VLOOKUP(N32,商品!$B$1:$E$1846,2,FALSE),"")
A33: 28 | B33: =IFERROR(VLOOKUP(B$5&TEXT($A33,"000"),商品!$B$1:$E$1846,1,FALSE),"") -> 03028 | C33: =IFERROR(VLOOKUP(B33,商品!$B$1:$E$1846,2,FALSE),"") -> あんかけちゃんぽん風 | E33: =IFERROR(VLOOKUP(E$5&TEXT($A33,"000"),商品!$B$1:$E$1846,1,FALSE),"") | F33: =IFERROR(VLOOKUP(E33,商品!$B$1:$E$1846,2,FALSE),"") | H33: =IFERROR(VLOOKUP(H$5&TEXT($A33,"000"),商品!$B$1:$E$1846,1,FALSE),"") | I33: =IFERROR(VLOOKUP(H33,商品!$B$1:$E$1846,2,FALSE),"") | K33: =IFERROR(VLOOKUP(K$5&TEXT($A33,"000"),商品!$B$1:$E$1846,1,FALSE),"") | L33: =IFERROR(VLOOKUP(K33,商品!$B$1:$E$1846,2,FALSE),"") | N33: =IFERROR(VLOOKUP(N$5&TEXT($A33,"000"),商品!$B$1:$E$1846,1,FALSE),"") | O33: =IFERROR(VLOOKUP(N33,商品!$B$1:$E$1846,2,FALSE),"")
A34: 29 | B34: =IFERROR(VLOOKUP(B$5&TEXT($A34,"000"),商品!$B$1:$E$1846,1,FALSE),"") -> 03029 | C34: =IFERROR(VLOOKUP(B34,商品!$B$1:$E$1846,2,FALSE),"") -> 白身魚のすりおろし野菜ソース | E34: =IFERROR(VLOOKUP(E$5&TEXT($A34,"000"),商品!$B$1:$E$1846,1,FALSE),"") | F34: =IFERROR(VLOOKUP(E34,商品!$B$1:$E$1846,2,FALSE),"") | H34: =IFERROR(VLOOKUP(H$5&TEXT($A34,"000"),商品!$B$1:$E$1846,1,FALSE),"") | I34: =IFERROR(VLOOKUP(H34,商品!$B$1:$E$1846,2,FALSE),"") | K34: =IFERROR(VLOOKUP(K$5&TEXT($A34,"000"),商品!$B$1:$E$1846,1,FALSE),"") | L34: =IFERROR(VLOOKUP(K34,商品!$B$1:$E$1846,2,FALSE),"") | N34: =IFERROR(VLOOKUP(N$5&TEXT($A34,"000"),商品!$B$1:$E$1846,1,FALSE),"") | O34: =IFERROR(VLOOKUP(N34,商品!$B$1:$E$1846,2,FALSE),"")
A35: 30 | B35: =IFERROR(VLOOKUP(B$5&TEXT($A35,"000"),商品!$B$1:$E$1846,1,FALSE),"") -> 03030 | C35: =IFERROR(VLOOKUP(B35,商品!$B$1:$E$1846,2,FALSE),"") -> 肉豆腐 | D35: 8 | E35: =IFERROR(VLOOKUP(E$5&TEXT($A35,"000"),商品!$B$1:$E$1846,1,FALSE),"") | F35: =IFERROR(VLOOKUP(E35,商品!$B$1:$E$1846,2,FALSE),"") | H35: =IFERROR(VLOOKUP(H$5&TEXT($A35,"000"),商品!$B$1:$E$1846,1,FALSE),"") | I35: =IFERROR(VLOOKUP(H35,商品!$B$1:$E$1846,2,FALSE),"") | K35: =IFERROR(VLOOKUP(K$5&TEXT($A35,"000"),商品!$B$1:$E$1846,1,FALSE),"") | L35: =IFERROR(VLOOKUP(K35,商品!$B$1:$E$1846,2,FALSE),"") | N35: =IFERROR(VLOOKUP(N$5&TEXT($A35,"000"),商品!$B$1:$E$1846,1,FALSE),"") | O35: =IFERROR(VLOOKUP(N35,商品!$B$1:$E$1846,2,FALSE),"")
A36: 31 | B36: =IFERROR(VLOOKUP(B$5&TEXT($A36,"000"),商品!$B$1:$E$1846,1,FALSE),"") -> 03031 | C36: =IFERROR(VLOOKUP(B36,商品!$B$1:$E$1846,2,FALSE),"") -> 親子煮 | D36: 4 | E36: =IFERROR(VLOOKUP(E$5&TEXT($A36,"000"),商品!$B$1:$E$1846,1,FALSE),"") | F36: =IFERROR(VLOOKUP(E36,商品!$B$1:$E$1846,2,FALSE),"") | H36: =IFERROR(VLOOKUP(H$5&TEXT($A36,"000"),商品!$B$1:$E$1846,1,FALSE),"") | I36: =IFERROR(VLOOKUP(H36,商品!$B$1:$E$1846,2,FALSE),"") | K36: =IFERROR(VLOOKUP(K$5&TEXT($A36,"000"),商品!$B$1:$E$1846,1,FALSE),"") | L36: =IFERROR(VLOOKUP(K36,商品!$B$1:$E$1846,2,FALSE),"") | N36: =IFERROR(VLOOKUP(N$5&TEXT($A36,"000"),商品!$B$1:$E$1846,1,FALSE),"") | O36: =IFERROR(VLOOKUP(N36,商品!$B$1:$E$1846,2,FALSE),"")
A37: 32 | B37: =IFERROR(VLOOKUP(B$5&TEXT($A37,"000"),商品!$B$1:$E$1846,1,FALSE),"") -> 03032 | C37: =IFERROR(VLOOKUP(B37,商品!$B$1:$E$1846,2,FALSE),"") -> 鶏肉の香味ソース | D37: 4 | E37: =IFERROR(VLOOKUP(E$5&TEXT($A37,"000"),商品!$B$1:$E$1846,1,FALSE),"") | F37: =IFERROR(VLOOKUP(E37,商品!$B$1:$E$1846,2,FALSE),"") | H37: =IFERROR(VLOOKUP(H$5&TEXT($A37,"000"),商品!$B$1:$E$1846,1,FALSE),"") | I37: =IFERROR(VLOOKUP(H37,商品!$B$1:$E$1846,2,FALSE),"") | K37: =IFERROR(VLOOKUP(K$5&TEXT($A37,"000"),商品!$B$1:$E$1846,1,FALSE),"") | L37: =IFERROR(VLOOKUP(K37,商品!$B$1:$E$1846,2,FALSE),"") | N37: =IFERROR(VLOOKUP(N$5&TEXT($A37,"000"),商品!$B$1:$E$1846,1,FALSE),"") | O37: =IFERROR(VLOOKUP(N37,商品!$B$1:$E$1846,2,FALSE),"")
A38: 33 | B38: =IFERROR(VLOOKUP(B$5&TEXT($A38,"000"),商品!$B$1:$E$1846,1,FALSE),"") -> 03033 | C38: =IFERROR(VLOOKUP(B38,商品!$B$1:$E$1846,2,FALSE),"") -> 酢豚 | D38: 8 | E38: =IFERROR(VLOOKUP(E$5&TEXT($A38,"000"),商品!$B$1:$E$1846,1,FALSE),"") | F38: =IFERROR(VLOOKUP(E38,商品!$B$1:$E$1846,2,FALSE),"") | H38: =IFERROR(VLOOKUP(H$5&TEXT($A38,"000"),商品!$B$1:$E$1846,1,FALSE),"") | I38: =IFERROR(VLOOKUP(H38,商品!$B$1:$E$1846,2,FALSE),"") | K38: =IFERROR(VLOOKUP(K$5&TEXT($A38,"000"),商品!$B$1:$E$1846,1,FALSE),"") | L38: =IFERROR(VLOOKUP(K38,商品!$B$1:$E$1846,2,FALSE),"") | N38: =IFERROR(VLOOKUP(N$5&TEXT($A38,"000"),商品!$B$1:$E$1846,1,FALSE),"") | O38: =IFERROR(VLOOKUP(N38,商品!$B$1:$E$1846,2,FALSE),"")
A39: 34 | B39: =IFERROR(VLOOKUP(B$5&TEXT($A39,"000"),商品!$B$1:$E$1846,1,FALSE),"") -> 03034 | C39: =IFERROR(VLOOKUP(B39,商品!$B$1:$E$1846,2,FALSE),"") -> 牛ごぼうのしぐれ煮 | E39: =IFERROR(VLOOKUP(E$5&TEXT($A39,"000"),商品!$B$1:$E$1846,1,FALSE),"") | F39: =IFERROR(VLOOKUP(E39,商品!$B$1:$E$1846,2,FALSE),"") | H39: =IFERROR(VLOOKUP(H$5&TEXT($A39,"000"),商品!$B$1:$E$1846,1,FALSE),"") | I39: =IFERROR(VLOOKUP(H39,商品!$B$1:$E$1846,2,FALSE),"") | K39: =IFERROR(VLOOKUP(K$5&TEXT($A39,"000"),商品!$B$1:$E$1846,1,FALSE),"") | L39: =IFERROR(VLOOKUP(K39,商品!$B$1:$E$1846,2,FALSE),"") | N39: =IFERROR(VLOOKUP(N$5&TEXT($A39,"000"),商品!$B$1:$E$1846,1,FALSE),"") | O39: =IFERROR(VLOOKUP(N39,商品!$B$1:$E$1846,2,FALSE),"")
A40: 35 | B40: =IFERROR(VLOOKUP(B$5&TEXT($A40,"000"),商品!$B$1:$E$1846,1,FALSE),"") -> 03035 | C40: =IFERROR(VLOOKUP(B40,商品!$B$1:$E$1846,2,FALSE),"") -> チキン南蛮宮崎風 | E40: =IFERROR(VLOOKUP(E$5&TEXT($A40,"000"),商品!$B$1:$E$1846,1,FALSE),"") | F40: =IFERROR(VLOOKUP(E40,商品!$B$1:$E$1846,2,FALSE),"") | H40: =IFERROR(VLOOKUP(H$5&TEXT($A40,"000"),商品!$B$1:$E$1846,1,FALSE),"") | I40: =IFERROR(VLOOKUP(H40,商品!$B$1:$E$1846,2,FALSE),"") | K40: =IFERROR(VLOOKUP(K$5&TEXT($A40,"000"),商品!$B$1:$E$1846,1,FALSE),"") | L40: =IFERROR(VLOOKUP(K40,商品!$B$1:$E$1846,2,FALSE),"") | N40: =IFERROR(VLOOKUP(N$5&TEXT($A40,"000"),商品!$B$1:$E$1846,1,FALSE),"") | O40: =IFERROR(VLOOKUP(N40,商品!$B$1:$E$1846,2,FALSE),"")
...

Sheet 取込用
A1: No. | B1: データ区分 | C1: 得意先コード | D1: 得意先名 | E1: 着日 | F1: 商品コード | G1: 商品名 | H1: 数量 | I1: ロット数 | J1: 商品分類 | K1: 商品分類名
A2: =ROW()-1 -> 1 | B2: 2 | C2: =発注書!$C$3 -> bb02787 | D2: =発注書!$D$3 -> イルミナジョブ＆カレッジ千葉中央校 | E2: =発注書!$I$1 -> 2025年12月9日 | F2: =IF(IFERROR(VLOOKUP(発注書!R5,商品分類!$B$2:$C$81,2,FALSE),"")="","",IFERROR(VLOOKUP(発注書!R5,商品分類!$B$2:$C$81,2,FALSE),"")&"001") -> 36001 | G2: =IF(発注書!R5="","",発注書!R5) -> 180gライス | H2: =発注書!R7 -> 72 | I2: 0 | J2: =LEFT(F2,2) -> 36 | K2: =発注書!$R$5 -> 180gライス
A3: =ROW()-1 -> 2 | B3: 2 | C3: =発注書!$C$3 -> bb02787 | D3: =発注書!$D$3 -> イルミナジョブ＆カレッジ千葉中央校 | E3: =発注書!$I$1 -> 2025年12月9日 | F3: =IF(IFERROR(VLOOKUP(発注書!R10,商品分類!$B$2:$C$81,2,FALSE),"")="","",IFERROR(VLOOKUP(発注書!R10,商品分類!$B$2:$C$81,2,FALSE),"")&"001") -> 37001 | G3: =IF(発注書!R10="","",発注書!R10) -> 150gライス | H3: =発注書!R12 -> 0 | I3: 0 | J3: =LEFT(F3,2) -> 37 | K3: =発注書!$R$10 -> 150gライス
A4: =ROW()-1 -> 3 | B4: 2 | C4: =発注書!$C$3 -> bb02787 | D4: =発注書!$D$3 -> イルミナジョブ＆カレッジ千葉中央校 | E4: =発注書!$I$1 -> 2025年12月9日 | F4: =IF(IFERROR(VLOOKUP(発注書!R15,商品分類!$B$2:$C$81,2,FALSE),"")="","",IFERROR(VLOOKUP(発注書!R15,商品分類!$B$2:$C$81,2,FALSE),"")&"001") | G4: =IF(発注書!R15="","",発注書!R15) | H4: =発注書!R17 -> 0 | I4: 0 | J4: =LEFT(F4,2) | K4: =発注書!$R$15 -> 0
A5: =ROW()-1 -> 4 | B5: 2 | C5: =発注書!$C$3 -> bb02787 | D5: =発注書!$D$3 -> イルミナジョブ＆カレッジ千葉中央校 | E5: =発注書!$I$1 -> 2025年12月9日 | F5: =発注書!B6 -> 03001 | G5: =発注書!C6 -> たらの牛だしあん | H5: =発注書!D6 -> 0 | I5: 0 | J5: =LEFT(F5,2) -> 03 | K5: =発注書!$C$5 -> 健康管理食選択型
A6: =ROW()-1 -> 5 | B6: 2 | C6: =発注書!$C$3 -> bb02787 | D6: =発注書!$D$3 -> イルミナジョブ＆カレッジ千葉中央校 | E6: =発注書!$I$1 -> 2025年12月9日 | F6: =発注書!B7 -> 03002 | G6: =発注書!C7 -> 豚バラ肉の豆乳ソースがけ | H6: =発注書!D7 -> 4 | I6: 0 | J6: =LEFT(F6,2) -> 03 | K6: =発注書!$C$5 -> 健康管理食選択型
A7: =ROW()-1 -> 6 | B7: 2 | C7: =発注書!$C$3 -> bb02787 | D7: =発注書!$D$3 -> イルミナジョブ＆カレッジ千葉中央校 | E7: =発注書!$I$1 -> 2025年12月9日 | F7: =発注書!B8 -> 03003 | G7: =発注書!C8 -> エビカツ | H7: =発注書!D8 -> 4 | I7: 0 | J7: =LEFT(F7,2) -> 03 | K7: =発注書!$C$5 -> 健康管理食選択型
A8: =ROW()-1 -> 7 | B8: 2 | C8: =発注書!$C$3 -> bb02787 | D8: =発注書!$D$3 -> イルミナジョブ＆カレッジ千葉中央校 | E8: =発注書!$I$1 -> 2025年12月9日 | F8: =発注書!B9 -> 03004 | G8: =発注書!C9 -> 鶏のから揚げ | H8: =発注書!D9 -> 4 | I8: 0 | J8: =LEFT(F8,2) -> 03 | K8: =発注書!$C$5 -> 健康管理食選択型
A9: =ROW()-1 -> 8 | B9: 2 | C9: =発注書!$C$3 -> bb02787 | D9: =発注書!$D$3 -> イルミナジョブ＆カレッジ千葉中央校 | E9: =発注書!$I$1 -> 2025年12月9日 | F9: =発注書!B10 -> 03005 | G9: =発注書!C10 -> すき焼き風煮 | H9: =発注書!D10 -> 8 | I9: 0 | J9: =LEFT(F9,2) -> 03 | K9: =発注書!$C$5 -> 健康管理食選択型
A10: =ROW()-1 -> 9 | B10: 2 | C10: =発注書!$C$3 -> bb02787 | D10: =発注書!$D$3 -> イルミナジョブ＆カレッジ千葉中央校 | E10: =発注書!$I$1 -> 2025年12月9日 | F10: =発注書!B11 -> 03006 | G10: =発注書!C11 -> 鶏肉のタンドリー風焼き | H10: =発注書!D11 -> 4 | I10: 0 | J10: =LEFT(F10,2) -> 03 | K10: =発注書!$C$5 -> 健康管理食選択型
A11: =ROW()-1 -> 10 | B11: 2 | C11: =発注書!$C$3 -> bb02787 | D11: =発注書!$D$3 -> イルミナジョブ＆カレッジ千葉中央校 | E11: =発注書!$I$1 -> 2025年12月9日 | F11: =発注書!B12 -> 03007 | G11: =発注書!C12 -> トマトソースのチーズハンバーグ | H11: =発注書!D12 -> 4 | I11: 0 | J11: =LEFT(F11,2) -> 03 | K11: =発注書!$C$5 -> 健康管理食選択型
A12: =ROW()-1 -> 11 | B12: 2 | C12: =発注書!$C$3 -> bb02787 | D12: =発注書!$D$3 -> イルミナジョブ＆カレッジ千葉中央校 | E12: =発注書!$I$1 -> 2025年12月9日 | F12: =発注書!B13 -> 03008 | G12: =発注書!C13 -> カレイのねぎ塩焼き | H12: =発注書!D13 -> 0 | I12: 0 | J12: =LEFT(F12,2) -> 03 | K12: =発注書!$C$5 -> 健康管理食選択型
A13: =ROW()-1 -> 12 | B13: 2 | C13: =発注書!$C$3 -> bb02787 | D13: =発注書!$D$3 -> イルミナジョブ＆カレッジ千葉中央校 | E13: =発注書!$I$1 -> 2025年12月9日 | F13: =発注書!B14 -> 03009 | G13: =発注書!C14 -> タラのみぞれかけ | H13: =発注書!D14 -> 0 | I13: 0 | J13: =LEFT(F13,2) -> 03 | K13: =発注書!$C$5 -> 健康管理食選択型
A14: =ROW()-1 -> 13 | B14: 2 | C14: =発注書!$C$3 -> bb02787 | D14: =発注書!$D$3 -> イルミナジョブ＆カレッジ千葉中央校 | E14: =発注書!$I$1 -> 2025年12月9日 | F14: =発注書!B15 -> 03010 | G14: =発注書!C15 -> 和風カツの卵とじ | H14: =発注書!D15 -> 0 | I14: 0 | J14: =LEFT(F14,2) -> 03 | K14: =発注書!$C$5 -> 健康管理食選択型
A15: =ROW()-1 -> 14 | B15: 2 | C15: =発注書!$C$3 -> bb02787 | D15: =発注書!$D$3 -> イルミナジョブ＆カレッジ千葉中央校 | E15: =発注書!$I$1 -> 2025年12月9日 | F15: =発注書!B16 -> 03011 | G15: =発注書!C16 -> みそカツ | H15: =発注書!D16 -> 0 | I15: 0 | J15: =LEFT(F15,2) -> 03 | K15: =発注書!$C$5 -> 健康管理食選択型
A16: =ROW()-1 -> 15 | B16: 2 | C16: =発注書!$C$3 -> bb02787 | D16: =発注書!$D$3 -> イルミナジョブ＆カレッジ千葉中央校 | E16: =発注書!$I$1 -> 2025年12月9日 | F16: =発注書!B17 -> 03012 | G16: =発注書!C17 -> 豚肉のタッカルビ風 | H16: =発注書!D17 -> 0 | I16: 0 | J16: =LEFT(F16,2) -> 03 | K16: =発注書!$C$5 -> 健康管理食選択型
... A85: =ROW()-1 -> 84 | B85: 2 | C85: =発注書!$C$3 -> bb02787 | D85: =発注書!$D$3 -> イルミナジョブ＆カレッジ千葉中央校 | E85: =発注書!$I$1 -> 2025年12月9日 | F85: =発注書!B86 | G85: =発注書!C86 | H85: =発注書!D86 -> 0 | I85: 0 | J85: =LEFT(F85,2) | K85: =発注書!$C$5 -> 健康管理食選択型
A86: =ROW()-1 -> 85 | B86: 2 | C86: =発注書!$C$3 -> bb02787 | D86: =発注書!$D$3 -> イルミナジョブ＆カレッジ千葉中央校 | E86: =発注書!$I$1 -> 2025年12月9日 | F86: =発注書!E6 | G86: =発注書!F6 | H86: =発注書!G6 -> 0 | I86: 0 | J86: =LEFT(F86,2) | K86: =発注書!$F$5 -> #N/A
A87: =ROW()-1 -> 86 | B87: 2 | C87: =発注書!$C$3 -> bb02787 | D87: =発注書!$D$3 -> イルミナジョブ＆カレッジ千葉中央校 | E87: =発注書!$I$1 -> 2025年12月9日 | F87: =発注書!E7 | G87: =発注書!F7 | H87: =発注書!G7 -> 0 | I87: 0 | J87: =LEFT(F87,2) | K87: =発注書!$F$5 -> #N/A
A88: =ROW()-1 -> 87 | B88: 2 | C88: =発注書!$C$3 -> bb02787 | D88: =発注書!$D$3 -> イルミナジョブ＆カレッジ千葉中央校 | E88: =発注書!$I$1 -> 2025年12月9日 | F88: =発注書!E8 | G88: =発注書!F8 | H88: =発注書!G8 -> 0 | I88: 0 | J88: =LEFT(F88,2) | K88: =発注書!$F$5 -> #N/A
A89: =ROW()-1 -> 88 | B89: 2 | C89: =発注書!$C$3 -> bb02787 | D89: =発注書!$D$3 -> イルミナジョブ＆カレッジ千葉中央校 | E89: =発注書!$I$1 -> 2025年12月9日 | F89: =発注書!E9 | G89: =発注書!F9 | H89: =発注書!G9 -> 0 | I89: 0 | J89: =LEFT(F89,2) | K89: =発注書!$F$5 -> #N/A
A90: =ROW()-1 -> 89 | B90: 2 | C90: =発注書!$C$3 -> bb02787 | D90: =発注書!$D$3 -> イルミナジョブ＆カレッジ千葉中央校 | E90: =発注書!$I$1 -> 2025年12月9日 | F90: =発注書!E10 | G90: =発注書!F10 | H90: =発注書!G10 -> 0 | I90: 0 | J90: =LEFT(F90,2) | K90: =発注書!$F$5 -> #N/A
A91: =ROW()-1 -> 90 | B91: 2 | C91: =発注書!$C$3 -> bb02787 | D91: =発注書!$D$3 -> イルミナジョブ＆カレッジ千葉中央校 | E91: =発注書!$I$1 -> 2025年12月9日 | F91: =発注書!E11 | G91: =発注書!F11 | H91: =発注書!G11 -> 0 | I91: 0 | J91: =LEFT(F91,2) | K91: =発注書!$F$5 -> #N/A
A92: =ROW()-1 -> 91 | B92: 2 | C92: =発注書!$C$3 -> bb02787 | D92: =発注書!$D$3 -> イルミナジョブ＆カレッジ千葉中央校 | E92: =発注書!$I$1 -> 2025年12月9日 | F92: =発注書!E12 | G92: =発注書!F12 | H92: =発注書!G12 -> 0 | I92: 0 | J92: =LEFT(F92,2) | K92: =発注書!$F$5 -> #N/A
A93: =ROW()-1 -> 92 | B93: 2 | C93: =発注書!$C$3 -> bb02787 | D93: =発注書!$D$3 -> イルミナジョブ＆カレッジ千葉中央校 | E93: =発注書!$I$1 -> 2025年12月9日 | F93: =発注書!E13 | G93: =発注書!F13 | H93: =発注書!G13 -> 0 | I93: 0 | J93: =LEFT(F93,2) | K93: =発注書!$F$5 -> #N/A
A94: =ROW()-1 -> 93 | B94: 2 | C94: =発注書!$C$3 -> bb02787 | D94: =発注書!$D$3 -> イルミナジョブ＆カレッジ千葉中央校 | E94: =発注書!$I$1 -> 2025年12月9日 | F94: =発注書!E14 | G94: =発注書!F14 | H94: =発注書!G14 -> 0 | I94: 0 | J94: =LEFT(F94,2) | K94: =発注書!$F$5 -> #N/A
A95: =ROW()-1 -> 94 | B95: 2 | C95: =発注書!$C$3 -> bb02787 | D95: =発注書!$D$3 -> イルミナジョブ＆カレッジ千葉中央校 | E95: =発注書!$I$1 -> 2025年12月9日 | F95: =発注書!E15 | G95: =発注書!F15 | H95: =発注書!G15 -> 0 | I95: 0 | J95: =LEFT(F95,2) | K95: =発注書!$F$5 -> #N/A
A96: =ROW()-1 -> 95 | B96: 2 | C96: =発注書!$C$3 -> bb02787 | D96: =発注書!$D$3 -> イルミナジョブ＆カレッジ千葉中央校 | E96: =発注書!$I$1 -> 2025年12月9日 | F96: =発注書!E16 | G96: =発注書!F16 | H96: =発注書!G16 -> 0 | I96: 0 | J96: =LEFT(F96,2) | K96: =発注書!$F$5 -> #N/A
A97: =ROW()-1 -> 96 | B97: 2 | C97: =発注書!$C$3 -> bb02787 | D97: =発注書!$D$3 -> イルミナジョブ＆カレッジ千葉中央校 | E97: =発注書!$I$1 -> 2025年12月9日 | F97: =発注書!E17 | G97: =発注書!F17 | H97: =発注書!G17 -> 0 | I97: 0 | J97: =LEFT(F97,2) | K97: =発注書!$F$5 -> #N/A
... A166: =ROW()-1 -> 165 | B166: 2 | C166: =発注書!$C$3 -> bb02787 | D166: =発注書!$D$3 -> イルミナジョブ＆カレッジ千葉中央校 | E166: =発注書!$I$1 -> 2025年12月9日 | F166: =発注書!E86 | G166: =発注書!F86 | H166: =発注書!G86 -> 0 | I166: 0 | J166: =LEFT(F166,2) | K166: =発注書!$F$5 -> #N/A
A167: =ROW()-1 -> 166 | B167: 2 | C167: =発注書!$C$3 -> bb02787 | D167: =発注書!$D$3 -> イルミナジョブ＆カレッジ千葉中央校 | E167: =発注書!$I$1 -> 2025年12月9日 | F167: =発注書!H6 | G167: =発注書!I6 | H167: =発注書!J6 -> 0 | I167: 0 | J167: =LEFT(F167,2) | K167: =発注書!$I$5 -> #N/A
A168: =ROW()-1 -> 167 | B168: 2 | C168: =発注書!$C$3 -> bb02787 | D168: =発注書!$D$3 -> イルミナジョブ＆カレッジ千葉中央校 | E168: =発注書!$I$1 -> 2025年12月9日 | F168: =発注書!H7 | G168: =発注書!I7 | H168: =発注書!J7 -> 0 | I168: 0 | J168: =LEFT(F168,2) | K168: =発注書!$I$5 -> #N/A
A169: =ROW()-1 -> 168 | B169: 2 | C169: =発注書!$C$3 -> bb02787 | D169: =発注書!$D$3 -> イルミナジョブ＆カレッジ千葉中央校 | E169: =発注書!$I$1 -> 2025年12月9日 | F169: =発注書!H8 | G169: =発注書!I8 | H169: =発注書!J8 -> 0 | I169: 0 | J169: =LEFT(F169,2) | K169: =発注書!$I$5 -> #N/A
A170: =ROW()-1 -> 169 | B170: 2 | C170: =発注書!$C$3 -> bb02787 | D170: =発注書!$D$3 -> イルミナジョブ＆カレッジ千葉中央校 | E170: =発注書!$I$1 -> 2025年12月9日 | F170: =発注書!H9 | G170: =発注書!I9 | H170: =発注書!J9 -> 0 | I170: 0 | J170: =LEFT(F170,2) | K170: =発注書!$I$5 -> #N/A
A171: =ROW()-1 -> 170 | B171: 2 | C171: =発注書!$C$3 -> bb02787 | D171: =発注書!$D$3 -> イルミナジョブ＆カレッジ千葉中央校 | E171: =発注書!$I$1 -> 2025年12月9日 | F171: =発注書!H10 | G171: =発注書!I10 | H171: =発注書!J10 -> 0 | I171: 0 | J171: =LEFT(F171,2) | K171: =発注書!$I$5 -> #N/A
A172: =ROW()-1 -> 171 | B172: 2 | C172: =発注書!$C$3 -> bb02787 | D172: =発注書!$D$3 -> イルミナジョブ＆カレッジ千葉中央校 | E172: =発注書!$I$1 -> 2025年12月9日 | F172: =発注書!H11 | G172: =発注書!I11 | H172: =発注書!J11 -> 0 | I172: 0 | J172: =LEFT(F172,2) | K172: =発注書!$I$5 -> #N/A
A173: =ROW()-1 -> 172 | B173: 2 | C173: =発注書!$C$3 -> bb02787 | D173: =発注書!$D$3 -> イルミナジョブ＆カレッジ千葉中央校 | E173: =発注書!$I$1 -> 2025年12月9日 | F173: =発注書!H12 | G173: =発注書!I12 | H173: =発注書!J12 -> 0 | I173: 0 | J173: =LEFT(F173,2) | K173: =発注書!$I$5 -> #N/A
A174: =ROW()-1 -> 173 | B174: 2 | C174: =発注書!$C$3 -> bb02787 | D174: =発注書!$D$3 -> イルミナジョブ＆カレッジ千葉中央校 | E174: =発注書!$I$1 -> 2025年12月9日 | F174: =発注書!H13 | G174: =発注書!I13 | H174: =発注書!J13 -> 0 | I174: 0 | J174: =LEFT(F174,2) | K174: =発注書!$I$5 -> #N/A
A175: =ROW()-1 -> 174 | B175: 2 | C175: =発注書!$C$3 -> bb02787 | D175: =発注書!$D$3 -> イルミナジョブ＆カレッジ千葉中央校 | E175: =発注書!$I$1 -> 2025年12月9日 | F175: =発注書!H14 | G175: =発注書!I14 | H175: =発注書!J14 -> 0 | I175: 0 | J175: =LEFT(F175,2) | K175: =発注書!$I$5 -> #N/A
A176: =ROW()-1 -> 175 | B176: 2 | C176: =発注書!$C$3 -> bb02787 | D176: =発注書!$D$3 -> イルミナジョブ＆カレッジ千葉中央校 | E176: =発注書!$I$1 -> 2025年12月9日 | F176: =発注書!H15 | G176: =発注書!I15 | H176: =発注書!J15 -> 0 | I176: 0 | J176: =LEFT(F176,2) | K176: =発注書!$I$5 -> #N/A
...

Sheet 商品分類
A1: 商品分類 | B1: 商品分類名 | C1: 商品分類2
A2: 01 | B2: 健康管理食昼 | C2: 01
A3: 02 | B3: 健康管理食夕 | C3: 02
A4: 03 | B4: 健康管理食選択型 | C4: 03
A5: 04 | B5: カロリー制限食 | C5: 04
A6: 05 | B6: 特別食 | C6: 05
A7: 06 | B7: たんぱく制限食 | C7: 06
A8: 07 | B8: 健康管理食(カロリー) | C8: 07
A9: 08 | B9: やわらか食 | C9: 08
A10: 09 | C10: 09
A11: 10 | B11: 健康管理食25種 | C11: 10
A12: 11 | B12: やわらか食 | C12: 11
A13: 12 | B13: ライトムース食 | C13: 12
A14: 13 | B14: ライトムース食 | C14: 13
A15: 14 | B15: ライトミール | C15: 14
A16: 15 | C16: 15
A17: 16 | B17: やわらか朝食 | C17: 16
A18: 17 | B18: ライトムース食 | C18: 17
A19: 18 | B19: ムース食 | C19: 18
A20: 19 | C20: 19
A21: 20 | C21: 20
A22: 21 | B22: ムース食 | C22: 21
A23: 22 | C23: 22
A24: 23 | C24: 23
A25: 24 | B25: ライス | C25: 24
A26: 25 | B26: 180gライス. | C26: 25
A27: 26 | B27: 150gライス. | C27: 26
A28: 27 | B28: 1枠朝食(メイン) | C28: 27
A29: 28 | B29: 1枠朝食(副菜) | C29: 28
A30: 29 | B30: ライトミール | C30: 29
A31: 30 | B31: やわらか朝食 | C31: 30
A32: 31 | B32: ライトムース食 | C32: 31
A33: 32 | B33: ライトミール | C33: 32
A34: 33 | B34: ライトミール | C34: 33
A35: 34 | B35: やわらか朝食 | C35: 34
A36: 35 | B36: ライトムース | C36: 35
... A50: 72 | B50: 冷凍庫レンタル代金 | C50: 72

Sheet 商品
A1: 商品分類 | B1: 商品コード | C1: 翌々月商品名
A2: 01 | B2: 01001 | C2: たらの牛だしあん
A3: 01 | B3: 01002 | C3: 豚バラ肉の豆乳ソースがけ
A4: 01 | B4: 01003 | C4: エビカツ
A5: 01 | B5: 01004 | C5: 鶏のから揚げ
A6: 01 | B6: 01005 | C6: すき焼き風煮
A7: 01 | B7: 01006 | C7: 鶏肉のタンドリー風焼き
A8: 01 | B8: 01007 | C8: トマトソースのチーズハンバーグ
A9: 01 | B9: 01008 | C9: カレイのねぎ塩焼き
A10: 01 | B10: 01009 | C10: タラのみぞれかけ
A11: 01 | B11: 01010 | C11: 和風カツの卵とじ
A12: 01 | B12: 01011 | C12: みそカツ
... A58: 01 | B58: 01057 | C58: 新春御膳
A59: 01 | B59: 01058
A60: 01 | B60: 01059 | C60: 鮭のゆずおろしあん
A61: 01 | B61: 01060 | C61: サーモンのパセリパン粉焼き
A62: 01 | B62: 01061 | C62: タラと山芋焼きのあごだしあん
A63: 01 | B63: 01062
A64: 01 | B64: 01063
A65: 01 | B65: 01064
A66: 01 | B66: 01065
A67: 01 | B67: 01066
A68: 01 | B68: 01067
A69: 01 | B69: 01068
A70: 01 | B70: 01069
A71: 01 | B71: 01070
A72: 01 | B72: 01071
A73: 01 | B73: 01073
A74: 01 | B74: 01074
... A81: 01 | B81: 01081
A82: 02 | B82: 02001 | C82: たらの牛だしあん
A83: 02 | B83: 02002 | C83: 豚バラ肉の豆乳ソースがけ
A84: 02 | B84: 02003 | C84: エビカツ
A85: 02 | B85: 02004 | C85: 鶏のから揚げ
A86: 02 | B86: 02005 | C86: すき焼き風煮
A87: 02 | B87: 02006 | C87: 鶏肉のタンドリー風焼き
A88: 02 | B88: 02007 | C88: トマトソースのチーズハンバーグ
A89: 02 | B89: 02008 | C89: カレイのねぎ塩焼き
A90: 02 | B90: 02009 | C90: タラのみぞれかけ
A91: 02 | B91: 02010 | C91: 和風カツの卵とじ
...
